<?xml version="1.0" encoding="UTF-8"?>
<!-- Generated by org.testng.reporters.JUnitReportReporter -->
<testsuite hostname="ShowStopper-PC" name="Tools_QA.AssrtionTest" tests="4" failures="2" timestamp="19 Jul 2016 20:34:29 GMT" time="0.031" errors="0">
  <testcase name="c" time="0.006" classname="Tools_QA.AssrtionTest">
    <failure type="java.lang.AssertionError" message="expected [2] but found [1]">
      <![CDATA[java.lang.AssertionError: expected [2] but found [1]
	at org.testng.Assert.fail(Assert.java:94)
	at org.testng.Assert.failNotEquals(Assert.java:496)
	at org.testng.Assert.assertEquals(Assert.java:125)
	at org.testng.Assert.assertEquals(Assert.java:372)
	at org.testng.Assert.assertEquals(Assert.java:382)
	at Tools_QA.AssrtionTest.c(AssrtionTest.java:32)
	at sun.reflect.NativeMethodAccessorImpl.invoke0(Native Method)
	at sun.reflect.NativeMethodAccessorImpl.invoke(Unknown Source)
	at sun.reflect.DelegatingMethodAccessorImpl.invoke(Unknown Source)
	at java.lang.reflect.Method.invoke(Unknown Source)
	at org.testng.internal.MethodInvocationHelper.invokeMethod(MethodInvocationHelper.java:85)
	at org.testng.internal.Invoker.invokeMethod(Invoker.java:639)
	at org.testng.internal.Invoker.invokeTestMethod(Invoker.java:816)
	at org.testng.internal.Invoker.invokeTestMethods(Invoker.java:1124)
	at org.testng.internal.TestMethodWorker.invokeTestMethods(TestMethodWorker.java:125)
	at org.testng.internal.TestMethodWorker.run(TestMethodWorker.java:108)
	at org.testng.TestRunner.privateRun(TestRunner.java:774)
	at org.testng.TestRunner.run(TestRunner.java:624)
	at org.testng.SuiteRunner.runTest(SuiteRunner.java:359)
	at org.testng.SuiteRunner.runSequentially(SuiteRunner.java:354)
	at org.testng.SuiteRunner.privateRun(SuiteRunner.java:312)
	at org.testng.SuiteRunner.run(SuiteRunner.java:261)
	at org.testng.SuiteRunnerWorker.runSuite(SuiteRunnerWorker.java:52)
	at org.testng.SuiteRunnerWorker.run(SuiteRunnerWorker.java:86)
	at org.testng.TestNG.runSuitesSequentially(TestNG.java:1215)
	at org.testng.TestNG.runSuitesLocally(TestNG.java:1140)
	at org.testng.TestNG.run(TestNG.java:1048)
	at org.testng.remote.AbstractRemoteTestNG.run(AbstractRemoteTestNG.java:126)
	at org.testng.remote.RemoteTestNG.initAndRun(RemoteTestNG.java:137)
	at org.testng.remote.RemoteTestNG.main(RemoteTestNG.java:58)
]]>
    </failure>
  </testcase> <!-- c -->
  <testcase name="a" time="0.017" classname="Tools_QA.AssrtionTest"/>
  <testcase name="d" time="0.005" classname="Tools_QA.AssrtionTest">
    <failure type="java.lang.AssertionError" message="expected [2] but found [1]">
      <![CDATA[java.lang.AssertionError: expected [2] but found [1]
	at org.testng.Assert.fail(Assert.java:94)
	at org.testng.Assert.failNotEquals(Assert.java:496)
	at org.testng.Assert.assertEquals(Assert.java:125)
	at org.testng.Assert.assertEquals(Assert.java:372)
	at org.testng.Assert.assertEquals(Assert.java:382)
	at Tools_QA.AssrtionTest.d(AssrtionTest.java:39)
	at sun.reflect.NativeMethodAccessorImpl.invoke0(Native Method)
	at sun.reflect.NativeMethodAccessorImpl.invoke(Unknown Source)
	at sun.reflect.DelegatingMethodAccessorImpl.invoke(Unknown Source)
	at java.lang.reflect.Method.invoke(Unknown Source)
	at org.testng.internal.MethodInvocationHelper.invokeMethod(MethodInvocationHelper.java:85)
	at org.testng.internal.Invoker.invokeMethod(Invoker.java:639)
	at org.testng.internal.Invoker.invokeTestMethod(Invoker.java:816)
	at org.testng.internal.Invoker.invokeTestMethods(Invoker.java:1124)
	at org.testng.internal.TestMethodWorker.invokeTestMethods(TestMethodWorker.java:125)
	at org.testng.internal.TestMethodWorker.run(TestMethodWorker.java:108)
	at org.testng.TestRunner.privateRun(TestRunner.java:774)
	at org.testng.TestRunner.run(TestRunner.java:624)
	at org.testng.SuiteRunner.runTest(SuiteRunner.java:359)
	at org.testng.SuiteRunner.runSequentially(SuiteRunner.java:354)
	at org.testng.SuiteRunner.privateRun(SuiteRunner.java:312)
	at org.testng.SuiteRunner.run(SuiteRunner.java:261)
	at org.testng.SuiteRunnerWorker.runSuite(SuiteRunnerWorker.java:52)
	at org.testng.SuiteRunnerWorker.run(SuiteRunnerWorker.java:86)
	at org.testng.TestNG.runSuitesSequentially(TestNG.java:1215)
	at org.testng.TestNG.runSuitesLocally(TestNG.java:1140)
	at org.testng.TestNG.run(TestNG.java:1048)
	at org.testng.remote.AbstractRemoteTestNG.run(AbstractRemoteTestNG.java:126)
	at org.testng.remote.RemoteTestNG.initAndRun(RemoteTestNG.java:137)
	at org.testng.remote.RemoteTestNG.main(RemoteTestNG.java:58)
]]>
    </failure>
  </testcase> <!-- d -->
  <testcase name="b" time="0.003" classname="Tools_QA.AssrtionTest"/>
</testsuite> <!-- Tools_QA.AssrtionTest -->
